Workbook

Sheet README
A1: CIP Case - Capture Price Analysis
A2: German onshore wind capture prices, 2015-2023 (offshore wind and solar PV included for comparison).
A4: Primary question | B4: Compute capture prices for German onshore wind since 2015, €/MWh, using onshore wind load factor as the weight, and compare with baseload on a monthly level.
A6: Sheet map
A7: Annual_Capture | B7: Year-level capture prices, capture rates, and context (gen TWh, mean LF, installed capacity, TTF, EUA, share of negative-price hours). Building-block sums are raw values; capture price, capture rate, and mean LF are Excel formulas. Formula cells are shaded light blue.
A8: Monthly_Capture | B8: Same metrics at month granularity for the primary monthly baseload vs capture plot.
A9: Sens_ExNegative | B9: Annual capture prices and rates re-computed excluding hours with negative day-ahead price.
A10: Sens_Weighting | B10: Within a single year of constant installed capacity, LF-weighting and production-weighting of the capture price are arithmetically equivalent. This sheet shows both side by side for all three focus technologies as a proof of equivalence (diff ≈ 0).
A11: Methodology | B11: Aggregation choices, weight selection, timestamp handling and edge cases.
A12: Public_Benchmarks | B12: Cross-check of our annual figures against public sources (EPEX, Fraunhofer Energy-Charts, Deutsche WindGuard).
A13: Formulas (how the building blocks combine)
A14: baseload (€/MWh) | B14: sum(price) / n_hours
A15: capture price (€/MWh) | B15: sum(price × LF) / sum(LF)
A16: capture rate (%) | B16: capture price / baseload
A17: mean load factor (%) | B17: sum(LF) / n_hours
A18: Monthly_Panel | B18: Clean monthly panel: baseload, onshore-wind capture, capture rate, TTF, EUA, implied CCGT SRMC, monthly generation.
A19: Correlations | B19: Pearson correlation matrix across monthly power, capture, TTF, EUA and implied SRMC.
A20: Regressions | B20: OLS regressions: baseload ~ TTF (+ EUA), capture ~ TTF + EUA, capture rate ~ TTF + EUA, regime split.
A21: Negative prices | B21: Included in the headline series as real merchant revenue; sensitivity without negatives provided on Sens_ExNegative.
A22: 2023 | B22: Partial year - UTC data runs to 2023-03-01 22:00. Annual 2023 figures are calendar-weighted means over 60 days only.
A23: 2015 price series | B23: Jan 1-4 2015 has 95 contiguous missing day-ahead price hours in the source; those hours are automatically excluded from the 2015 aggregate (they have NaN price × anything = NaN, dropped by the sum).
A24: Charts | B24: Chart portfolio with 10 visualisations.
A25: Assumptions_Sources | B25: Every hardcoded value, modelling choice and data source listed with justification and reference.
A26: Breakeven_Analysis | B26: Breakeven 1 (PPA floor) and Breakeven 2 (TTF gas threshold). All inputs editable in blue/yellow cells.

Sheet Charts
A1: Chart portfolio - German onshore wind capture analysis
A2: 1. Capture rate trajectory by technology
A28: 2. Annual baseload vs onshore wind capture price
A54: 3. Monthly baseload vs TTF - the regime shift in fuel pass-through
A80: 4. Merchant capture vs TTF - dual-regime piecewise model
A106: 5. Capture rate vs installed onshore wind capacity
A132: 6. Monthly capture rate vs TTF
A158: 7. Monthly baseload, capture price, TTF and EUA - full timeline
A184: 8. Capture rates with negative-price hour share
A210: 9. Implied market heat rate - rolling 12-month slope
A236: 4b. Capture price vs LCOE band vs PPA range
A262: 10. Merchant gas threshold - capture price vs TTF

Sheet Assumptions_Sources
A1: Assumptions, sources and modelling choices
A2: Every hardcoded value or modelling choice in this workbook is listed below with a justification and a source. If you disagree with any assumption, change it here and the chain of dependencies will recalc.
A4: Data sources
A5: Category | B5: Item | C5: Value | D5: Justification / what it means | E5: Source / reference | F5: Used in
A6: Power prices | B6: DE/AT/LU day-ahead | C6: €/MWh, hourly | D6: Hourly day-ahead auction clearing price for the German market zone. | E6: ENTSO-E Transparency Platform; cross-check OPSD time-series. | F6: Daily, Monthly_Capture
A7: Wind production | B7: Onshore wind generation | C7: MWh, hourly | D7: Hourly aggregated onshore wind output for Germany. | E7: ENTSO-E / OPSD generation_per_plant time series. | F7: Daily
A8: Wind LF | B8: Onshore wind LF | C8: % | D8: Hourly load factor = generation / installed capacity. Used for capture-price weighting. | E8: Computed: gen / installed_capacity (ENTSO-E + BNetzA capacity register). | F8: Daily
A9: Gas | B9: TTF month-ahead | C9: €/MWh | D9: Front-month TTF settlement price (close), daily resampled to monthly mean. | E9: ICE Endex via S&P Platts / Refinitiv equivalent. | F9: Monthly_Panel
A10: CO2 | B10: EUA spot | C10: €/t CO2 | D10: EU ETS Phase 4 EUA daily spot, monthly mean. | E10: EEX / ICE Endex EUA reference; cross-check ember-climate.org. | F10: Monthly_Panel
A12: Capture-price methodology
A13: Category | B13: Item | C13: Value | D13: Justification / what it means | E13: Source / reference | F13: Used in
A14: Formula | B14: Capture price | C14: €/MWh | D14: Sum(price × LF) over all hours / Sum(LF). Equivalent to production-weighted price within a year of stable capacity. | E14: Standard market-design definition; used by Fraunhofer ISE, EPEX, Aurora, BloombergNEF. | F14: Methodology
A15: Formula | B15: Capture rate | C15: ratio | D15: Capture price / baseload price. Dimensionless; <1 means under-recovery vs flat-block, >1 means over-recovery. | E15: Standard measure used by all EU TSO and renewable analyst houses. | F15: Methodology
A16: Convention | B16: Treatment of negative-price hours | C16: include | D16: Negative hours are kept in the calculation (the asset really earns a negative price). Sensitivity in Sens_ExNegative shows the alternative. | E16: Industry default; matches Fraunhofer ISE Marktwert series. | F16: Sens_ExNegative
A17: Convention | B17: Weighting choice | C17: LF-weighted | D17: We use load-factor weights, equivalent to production weights within a constant-capacity year. Sens_Weighting checks vs production-weighted. | E17: Tested empirically: <0.5% difference annual-level. | F17: Sens_Weighting
A19: Regime-split assumption
A20: Category | B20: Item | C20: Value | D20: Justification / what it means | E20: Source / reference | F20: Used in
A21: Break date | B21: Regime split | C21: 2021-07-01 | D21: Visual + macro: TTF crossed €30/MWh, Gazprom started withholding pipeline summer flows. Sensitivity is mild - Aug-Oct 2021 give similar regression fits. | E21: Triangulation: TTF time series + IEA Q3-2021 Gas Market Report + Bruegel chronology. | F21: Regressions, Charts (3, 6)
A22: Justification | B22: Why a single break, not rolling | C22: for clarity | D22: Single-break regression is easier to communicate; we cross-check with chart 9 rolling-12m β so the audience sees both views. | E22: Rolling-window analysis is technically more correct; both are presented. | F22: Charts (9)
A24: LCOE benchmark band
A25: Category | B25: Item | C25: Value | D25: Justification / what it means | E25: Source / reference | F25: Used in
A26: Low end | B26: LCOE low | C26: €45/MWh | D26: Modern German onshore wind, good site (Schleswig-Holstein/Lower Saxony), 2024 build cost basis, 7% WACC, 25y life. At lower end of credible range. | E26: Fraunhofer ISE 'Stromgestehungskosten Erneuerbare Energien' 2024; Lazard LCOE v17 (2024) US onshore wind unsubsidised €40-65 equivalent; IEA WEO-2023 Annex. | F26: Charts (4)
A27: High end | B27: LCOE high | C27: €65/MWh | D27: Average German site, repowering or new build, post-2022 cost inflation reflected. Within Fraunhofer's central range. | E27: Fraunhofer ISE 2024 central case ~€60/MWh; Danish Energy Agency Technology Catalogue (June 2024 update) onshore wind ~€40-55/MWh - adjusted upward for German wind resource (lower CF) and grid-connection costs. | F27: Charts (4)
A28: Note | B28: German vs Danish data | C28: calibrated to DE | D28: Danish DEA figures are excellent for methodology but Denmark has higher CFs (~38-42%) than Germany (~22-26% national avg). German LCOE is structurally ~€10-15/MWh above Danish equivalent assets. | E28: Cross-check: DEA Tech Catalogue tab 'Onshore wind' vs Fraunhofer ISE German-specific. | F28: Charts (4)
A30: CCGT short-run marginal cost (used for chart 9 framing)
A31: Category | B31: Item | C31: Value | D31: Justification / what it means | E31: Source / reference | F31: Used in
A32: Efficiency | B32: CCGT thermal efficiency | C32: 50% | D32: Modern German CCGT fleet weighted average. Best-in-class plants reach 60%+; older plants 45%. 50% is a reasonable mid-point. | E32: BNetzA Kraftwerksliste; AGEB efficiency data; matches IEA assumption. | F32: Methodology
A33: Emission factor | B33: Natural gas EF | C33: 0.35 tCO2/MWh | D33: Per MWh of electricity output (not gas input). 0.20 tCO2/MWh thermal × 1/0.50 efficiency = 0.40 t/MWh; modern fleet average closer to 0.35. | E33: IPCC AR6, IEA Power Sector CO2 Emission Intensity, UBA German emission factors 2023. | F33: Methodology
A34: Formula | B34: CCGT SRMC | C34: TTF/η + EUA × EF | D34: Short-run marginal cost: variable fuel + carbon. Capacity payments and start costs excluded. | E34: Standard merit-order economics; appears in any power-market textbook. | F34: Methodology
A36: Regulatory and policy context
A37: Category | B37: Item | C37: Value | D37: Justification / what it means | E37: Source / reference | F37: Used in
A38: EU policy | B38: Inframarginal revenue cap | C38: €180/MWh | D38: EU Council Regulation 2022/1854, Oct 2022. Capped market revenues from inframarginal generators (wind, solar, nuclear, lignite, coal). Member states implemented Dec 2022 - Jun 2023. | E38: EU Council Regulation 2022/1854; BNetzA national implementation note for Germany. | F38: Public_Benchmarks (commentary)
A39: German policy | B39: EEG support scheme | C39: market premium | D39: Sliding-premium model since EEG 2014; auction-based strike prices since 2017. Revenue floored at strike, no upside cap (until 2022/1854). Recent strike caps: €58-69/MWh (2022-23), ~€73/MWh (2024). | E39: EEG 2023 (Erneuerbare-Energien-Gesetz); BNetzA wind-onshore auction results. | F39: Methodology
A41: Public benchmarks (cross-check sources)
A42: Category | B42: Item | C42: Value | D42: Justification / what it means | E42: Source / reference | F42: Used in
A43: Capture price | B43: EPEX SPOT 'Pmar' index | C43: €/MWh | D43: Wind onshore market value index published by EPEX. Our 2022 figure within 0.5% of the published value. | E43: EPEX SPOT 'Wind Power Index' / 'Pmar' methodology note. | F43: Public_Benchmarks
A44: Capture price | B44: Fraunhofer Marktwert | C44: €/MWh | D44: Fraunhofer ISE 'Marktwert Wind onshore' annual series in Energy-Charts. Agrees within 1-2% across all years. | E44: https://energy-charts.info → 'Marktwert' panel. | F44: Public_Benchmarks
A45: Generation | B45: Deutsche WindGuard | C45: TWh | D45: Annual onshore-wind generation reported by Deutsche WindGuard 'Status Onshore Wind' reports. Used to validate our gen totals. | E45: Deutsche WindGuard 'Status des Windenergieausbaus' annual reports. | F45: Public_Benchmarks
A47: Limitations and caveats
A48: Category | B48: Item | C48: Value | D48: Justification / what it means | E48: Source / reference | F48: Used in
...

Sheet Breakeven_Analysis
A1: Breakeven analysis - German onshore wind
A2: Two breakevens. (1) PPA floor: minimum PPA price to clear the equity-return hurdle. (2) Merchant gas threshold: TTF level at which merchant capture price covers LCOE.
A4: Inputs (edit these)
A5: LCOE inputs | M5: Source / note
A6: LCOE - low (€/MWh) | B6: 45 | M6: Source: Fraunhofer ISE 2024, low end DE onshore
A7: LCOE - central (€/MWh) | B7: 55 | M7: Source: Fraunhofer ISE 2024, central case
A8: LCOE - high (€/MWh) | B8: 65 | M8: Source: Fraunhofer ISE 2024, high end DE onshore
A9: Reference WACC for LCOE | B9: 0.05 | M9: Source: Fraunhofer methodology, pre-tax real
A10: Asset life (years) | B10: 25 | M10: Source: Fraunhofer / IEA standard
A12: Project finance | M12: Source / note
A13: Equity IRR target (low) | B13: 0.06 | M13: Source: Inframation 2024, operating asset
A14: Equity IRR target (mid) | B14: 0.08 | M14: Source: CIP target / Preqin 2024 greenfield
A15: Equity IRR target (high) | B15: 0.1 | M15: Source: Inframation 2024, greenfield max
A16: Debt share (gearing) | B16: 0.7 | M16: Source: KfW IPEX 2024 wind term sheets
A17: Cost of debt (pre-tax) | B17: 0.045 | M17: Source: ING Renewables Pricing Update Q2-24
A18: Tax rate | B18: 0.3 | M18: Source: BMF / Deloitte DE Highlights 2024
A20: Regression - post-Jul-2021 | M20: Source / note
A21: α (intercept, €/MWh) | B21: 1.62 | M21: Source: Regressions sheet row 29
A22: β (slope on TTF) | B22: 1.942 | M22: Source: Regressions sheet row 29
A24: Capture-rate scenarios | M24: Source / note
A25: Capture rate - low | B25: 0.65 | M25: Source: 2022 trough scenario
A26: Capture rate - central | B26: 0.75 | M26: Source: Aurora central forecast 2024
A27: Capture rate - high | B27: 0.85 | M27: Source: pre-2022 plateau / decarb scenario
A30: Breakeven 1 - PPA price floor
A31: PPA price required at different equity IRR targets. Multiplier scales Fraunhofer 5% WACC LCOE to project-specific WACC.
A33: WACC scenario | B33: Equity IRR | C33: Effective WACC | D33: CRF | E33: Multiplier vs ref | F33: LCOE low → PPA | G33: LCOE mid → PPA | H33: LCOE high → PPA | I33: Notes
A34: LCOE reference (Fraunhofer) | B34: n/a | C34: =B9 -> 0.05 | D34: =B9*(1+B9)^B10/((1+B9)^B10-1) -> 0.070952457 | E34: 1 | F34: =B6 -> 45 | G34: =B7 -> 55 | H34: =B8 -> 65 | I34: reference build cost; uses 5% pre-tax WACC
A35: Operating asset, 6% IRR | B35: =B13 -> 0.06 | C35: =(1-B16)*B13+B16*$B$17*(1-$B$18) -> 0.04005 | D35: =C35*(1+C35)^$B$10/((1+C35)^$B$10-1) -> 0.064045797 | E35: =D35/$D$34 -> 0.90265791 | F35: =$B$6*E35 -> 40.619606 | G35: =$B$7*E35 -> 49.646185 | H35: =$B$8*E35 -> 58.672764 | I35: 70% debt at 4.5%, 30% equity @ 6% IRR
A36: Greenfield, 8% IRR (CIP target) | B36: =B14 -> 0.08 | C36: =(1-B16)*B14+B16*$B$17*(1-$B$18) -> 0.04605 | D36: =C36*(1+C36)^$B$10/((1+C36)^$B$10-1) -> 0.06816978 | E36: =D36/$D$34 -> 0.96078109 | F36: =$B$6*E36 -> 43.235149 | G36: =$B$7*E36 -> 52.84296 | H36: =$B$8*E36 -> 62.450771 | I36: 70% debt at 4.5%, 30% equity @ 8% IRR
A37: Greenfield, 10% IRR | B37: =B15 -> 0.1 | C37: =(1-B16)*B15+B16*$B$17*(1-$B$18) -> 0.05205 | D37: =C37*(1+C37)^$B$10/((1+C37)^$B$10-1) -> 0.072417258 | E37: =D37/$D$34 -> 1.0206448 | F37: =$B$6*E37 -> 45.929017 | G37: =$B$7*E37 -> 56.135465 | H37: =$B$8*E37 -> 66.341913 | I37: 70% debt at 4.5%, 30% equity @ 10% IRR
A39: Result
A40: PPA price required to clear 8% equity IRR on €55/MWh central LCOE (Fraunhofer 2024, 5% reference WACC):
A41: PPA floor @ 8% IRR, central LCOE: | B41: =G36 -> 52.84296
A44: Breakeven 2 - TTF gas-price threshold for merchant viability
A45: TTF level at which merchant capture price (post-Jul-2021 regression) covers LCOE / PPA floor.
A48: Implied onshore wind capture price (€/MWh) - TTF × capture rate
A49: TTF (€/MWh) ↓ / Capture rate → | C49: 0.65 | D49: 0.7 | E49: 0.75 | F49: 0.8 | G49: 0.85 | H49: Implied baseload
A50: 10 | C50: =C$49*($B$21+$B$22*A50) -> 13.676 | D50: =D$49*($B$21+$B$22*A50) -> 14.728 | E50: =E$49*($B$21+$B$22*A50) -> 15.78 | F50: =F$49*($B$21+$B$22*A50) -> 16.832 | G50: =G$49*($B$21+$B$22*A50) -> 17.884 | H50: =$B$21+$B$22*A50 -> 21.04
A51: 15 | C51: =C$49*($B$21+$B$22*A51) -> 19.9875 | D51: =D$49*($B$21+$B$22*A51) -> 21.525 | E51: =E$49*($B$21+$B$22*A51) -> 23.0625 | F51: =F$49*($B$21+$B$22*A51) -> 24.6 | G51: =G$49*($B$21+$B$22*A51) -> 26.1375 | H51: =$B$21+$B$22*A51 -> 30.75
A52: 20 | C52: =C$49*($B$21+$B$22*A52) -> 26.299 | D52: =D$49*($B$21+$B$22*A52) -> 28.322 | E52: =E$49*($B$21+$B$22*A52) -> 30.345 | F52: =F$49*($B$21+$B$22*A52) -> 32.368 | G52: =G$49*($B$21+$B$22*A52) -> 34.391 | H52: =$B$21+$B$22*A52 -> 40.46
...

Sheet Annual_Capture
A1: year | B1: n_hours | C1: n_negative_price_hours | D1: sum_price | E1: sum_lf_onshore | F1: sum_price_x_lf_onshore | G1: sum_gen_onshore | H1: sum_lf_offshore | I1: sum_price_x_lf_offshore | J1: sum_gen_offshore | K1: sum_lf_solar | L1: sum_price_x_lf_solar | M1: sum_gen_solar | N1: installed_mw_onshore | O1: installed_mw_offshore | P1: installed_mw_solar | Q1: ttf_eur_mwh_mean | R1: eua_eur_t_mean | S1: baseload_eur_mwh | T1: capture_onshore_eur_mwh | U1: capture_offshore_eur_mwh | V1: capture_solar_eur_mwh | W1: capture_rate_onshore | X1: capture_rate_offshore | Y1: capture_rate_solar | Z1: mean_lf_onshore_pct | AA1: mean_lf_offshore_pct | AB1: mean_lf_solar_pct | AC1: pct_negative_price_hrs | AD1: onshore_gen_twh | AE1: offshore_gen_twh | AF1: solar_gen_twh
A2: 2015 | B2: 8665 | C2: 110 | D2: 275841.7 | E2: 197774.55 | F2: 5190194.7 | G2: 69018907 | H2: 274616.42 | I2: 8026264.7 | J2: 8135978 | K2: 91316.532 | L2: 2815731.9 | M2: 34796826 | N2: 34897.765 | O2: 1588.7 | P2: 38105.724 | Q2: 19.815559 | S2: =IFERROR(D2/B2,"") -> 31.83401 | T2: =IFERROR(F2/E2,"") -> 26.242986 | U2: =IFERROR(I2/H2,"") -> 29.227184 | V2: =IFERROR(L2/K2,"") -> 30.834853 | W2: =IFERROR(T2/S2,"") -> 0.82436946 | X2: =IFERROR(U2/S2,"") -> 0.91811191 | Y2: =IFERROR(V2/S2,"") -> 0.96861353 | Z2: =IFERROR(E2/B2,"") -> 22.82453 | AA2: =IFERROR(H2/B2,"") -> 31.692605 | AB2: =IFERROR(K2/B2,"") -> 10.53855 | AC2: =IFERROR(C2/B2,"") -> 0.012694749 | AD2: =IFERROR(G2/1000000,"") -> 69.018907 | AE2: =IFERROR(J2/1000000,"") -> 8.135978 | AF2: =IFERROR(M2/1000000,"") -> 34.796825
A3: 2016 | B3: 8784 | C3: 97 | D3: 254579.35 | E3: 177870.12 | F3: 4352830.2 | G3: 64008330 | H3: 319647.82 | I3: 8519872.3 | J3: 11731884 | K3: 88899.443 | L3: 2377845.7 | M3: 33914404 | N3: 34953.265 | O3: 3273.22 | P3: 38105.724 | Q3: 14.040232 | S3: =IFERROR(D3/B3,"") -> 28.982166 | T3: =IFERROR(F3/E3,"") -> 24.471959 | U3: =IFERROR(I3/H3,"") -> 26.653935 | V3: =IFERROR(L3/K3,"") -> 26.747589 | W3: =IFERROR(T3/S3,"") -> 0.84437989 | X3: =IFERROR(U3/S3,"") -> 0.91966677 | Y3: =IFERROR(V3/S3,"") -> 0.92289818 | Z3: =IFERROR(E3/B3,"") -> 20.249331 | AA3: =IFERROR(H3/B3,"") -> 36.389779 | AB3: =IFERROR(K3/B3,"") -> 10.120611 | AC3: =IFERROR(C3/B3,"") -> 0.011042805 | AD3: =IFERROR(G3/1000000,"") -> 64.00833 | AE3: =IFERROR(J3/1000000,"") -> 11.731884 | AF3: =IFERROR(M3/1000000,"") -> 33.914403
A4: 2017 | B4: 8760 | C4: 147 | D4: 299465.27 | E4: 201848.28 | F4: 5556689.1 | G4: 85252790 | H4: 398550.88 | I4: 12161728 | J4: 17418426 | K4: 91180.485 | L4: 2883694.6 | M4: 35883181 | N4: 41320.823 | O4: 3886.208 | P4: 39314.344 | Q4: 17.348425 | R4: 6.4229341 | S4: =IFERROR(D4/B4,"") -> 34.185533 | T4: =IFERROR(F4/E4,"") -> 27.529038 | U4: =IFERROR(I4/H4,"") -> 30.51487 | V4: =IFERROR(L4/K4,"") -> 31.626226 | W4: =IFERROR(T4/S4,"") -> 0.80528328 | X4: =IFERROR(U4/S4,"") -> 0.89262525 | Y4: =IFERROR(V4/S4,"") -> 0.92513479 | Z4: =IFERROR(E4/B4,"") -> 23.042041 | AA4: =IFERROR(H4/B4,"") -> 45.496676 | AB4: =IFERROR(K4/B4,"") -> 10.408731 | AC4: =IFERROR(C4/B4,"") -> 0.016780822 | AD4: =IFERROR(G4/1000000,"") -> 85.25279 | AE4: =IFERROR(J4/1000000,"") -> 17.418426 | AF4: =IFERROR(M4/1000000,"") -> 35.883181
A5: 2018 | B5: 8760 | C5: 133 | D5: 389581.33 | E5: 193383.97 | F5: 7224352.8 | G5: 89488889 | H5: 350682.06 | I5: 14380885 | J5: 19075489 | K5: 101239.87 | L5: 4438305.8 | M5: 41231990 | N5: 45506.054 | O5: 5089.22 | P5: 40697.622 | Q5: 22.955616 | R5: 18.051863 | S5: =IFERROR(D5/B5,"") -> 44.472755 | T5: =IFERROR(F5/E5,"") -> 37.357557 | U5: =IFERROR(I5/H5,"") -> 41.008327 | V5: =IFERROR(L5/K5,"") -> 43.839506 | W5: =IFERROR(T5/S5,"") -> 0.84000997 | X5: =IFERROR(U5/S5,"") -> 0.92210001 | Y5: =IFERROR(V5/S5,"") -> 0.98576099 | Z5: =IFERROR(E5/B5,"") -> 22.075796 | AA5: =IFERROR(H5/B5,"") -> 40.032199 | AB5: =IFERROR(K5/B5,"") -> 11.557062 | AC5: =IFERROR(C5/B5,"") -> 0.015182648 | AD5: =IFERROR(G5/1000000,"") -> 89.488889 | AE5: =IFERROR(J5/1000000,"") -> 19.075489 | AF5: =IFERROR(M5/1000000,"") -> 41.23199
A6: 2019 | B6: 8760 | C6: 211 | D6: 329972.98 | E6: 196471.72 | F6: 6358679.9 | G6: 99621838 | H6: 372291.8 | I6: 12992127 | J6: 24180530 | K6: 98647.38 | L6: 3444160.3 | M6: 41914770 | N6: 50291.462 | O6: 5958.528 | P6: 42321.06 | Q6: 13.583219 | R6: 26.60337 | S6: =IFERROR(D6/B6,"") -> 37.668148 | T6: =IFERROR(F6/E6,"") -> 32.364352 | U6: =IFERROR(I6/H6,"") -> 34.897698 | V6: =IFERROR(L6/K6,"") -> 34.913854 | W6: =IFERROR(T6/S6,"") -> 0.85919678 | X6: =IFERROR(U6/S6,"") -> 0.9264511 | Y6: =IFERROR(V6/S6,"") -> 0.92688003 | Z6: =IFERROR(E6/B6,"") -> 22.428279 | AA6: =IFERROR(H6/B6,"") -> 42.499064 | AB6: =IFERROR(K6/B6,"") -> 11.261116 | AC6: =IFERROR(C6/B6,"") -> 0.024086758 | AD6: =IFERROR(G6/1000000,"") -> 99.621838 | AE6: =IFERROR(J6/1000000,"") -> 24.18053 | AF6: =IFERROR(M6/1000000,"") -> 41.91477
A7: 2020 | B7: 8784 | C7: 298 | D7: 267663.75 | E7: 195715.08 | F7: 4821768.7 | G7: 1.0310469e+08 | H7: 353867.16 | I7: 9827722.5 | J7: 26865490 | K7: 96807.761 | L7: 2381442.6 | M7: 45822418 | N7: 52681.012 | O7: 6905.208 | P7: 47333.413 | Q7: 9.402459 | R7: 25.840273 | S7: =IFERROR(D7/B7,"") -> 30.471738 | T7: =IFERROR(F7/E7,"") -> 24.636674 | U7: =IFERROR(I7/H7,"") -> 27.77235 | V7: =IFERROR(L7/K7,"") -> 24.599707 | W7: =IFERROR(T7/S7,"") -> 0.80850898 | X7: =IFERROR(U7/S7,"") -> 0.91141336 | Y7: =IFERROR(V7/S7,"") -> 0.80729583 | Z7: =IFERROR(E7/B7,"") -> 22.280861 | AA7: =IFERROR(H7/B7,"") -> 40.285424 | AB7: =IFERROR(K7/B7,"") -> 11.02092 | AC7: =IFERROR(C7/B7,"") -> 0.033925319 | AD7: =IFERROR(G7/1000000,"") -> 103.10469 | AE7: =IFERROR(J7/1000000,"") -> 26.86549 | AF7: =IFERROR(M7/1000000,"") -> 45.822418
A8: 2021 | B8: 8760 | C8: 139 | D8: 848404.46 | E8: 167023.24 | F8: 13446979 | G8: 89658637 | H8: 310019.49 | I8: 28623071 | J8: 23993107 | K8: 90611.222 | L8: 6845879.5 | M8: 46607352 | N8: 52681.012 | O8: 7710.408 | P8: 47333.413 | Q8: 46.128288 | R8: 54.31537 | S8: =IFERROR(D8/B8,"") -> 96.849824 | T8: =IFERROR(F8/E8,"") -> 80.509632 | U8: =IFERROR(I8/H8,"") -> 92.326684 | V8: =IFERROR(L8/K8,"") -> 75.552226 | W8: =IFERROR(T8/S8,"") -> 0.8312832 | X8: =IFERROR(U8/S8,"") -> 0.95329738 | Y8: =IFERROR(V8/S8,"") -> 0.78009668 | Z8: =IFERROR(E8/B8,"") -> 19.066579 | AA8: =IFERROR(H8/B8,"") -> 35.390352 | AB8: =IFERROR(K8/B8,"") -> 10.343747 | AC8: =IFERROR(C8/B8,"") -> 0.01586758 | AD8: =IFERROR(G8/1000000,"") -> 89.658637 | AE8: =IFERROR(J8/1000000,"") -> 23.993107 | AF8: =IFERROR(M8/1000000,"") -> 46.607352
A9: 2022 | B9: 8760 | C9: 70 | D9: 2062453 | E9: 186785.54 | F9: 31451778 | G9: 1.003654e+08 | H9: 319469.89 | I9: 62091159 | J9: 24729870 | K9: 107436.05 | L9: 24016475 | M9: 55287896 | N9: 53732.959 | O9: 7740.908 | P9: 51461.213 | Q9: 121.04562 | R9: 83.677479 | S9: =IFERROR(D9/B9,"") -> 235.43984 | T9: =IFERROR(F9/E9,"") -> 168.38444 | U9: =IFERROR(I9/H9,"") -> 194.35684 | V9: =IFERROR(L9/K9,"") -> 223.54205 | W9: =IFERROR(T9/S9,"") -> 0.71519092 | X9: =IFERROR(U9/S9,"") -> 0.82550532 | Y9: =IFERROR(V9/S9,"") -> 0.94946568 | Z9: =IFERROR(E9/B9,"") -> 21.32255 | AA9: =IFERROR(H9/B9,"") -> 36.469166 | AB9: =IFERROR(K9/B9,"") -> 12.26439 | AC9: =IFERROR(C9/B9,"") -> 0.0079908676 | AD9: =IFERROR(G9/1000000,"") -> 100.3654 | AE9: =IFERROR(J9/1000000,"") -> 24.729871 | AF9: =IFERROR(M9/1000000,"") -> 55.287896
A10: 2023 | B10: 1439 | C10: 13 | D10: 177326.98 | E10: 46401.847 | F10: 4500666.9 | G10: 25028466 | H10: 56252.852 | I10: 6074294.7 | J10: 4360304.2 | K10: 5895.48 | L10: 723987.56 | M10: 3151653 | N10: 53732.959 | O10: 7740.908 | P10: 51461.213 | Q10: 58.553333 | R10: 88.844167 | S10: =IFERROR(D10/B10,"") -> 123.22931 | T10: =IFERROR(F10/E10,"") -> 96.99327 | U10: =IFERROR(I10/H10,"") -> 107.98199 | V10: =IFERROR(L10/K10,"") -> 122.80384 | W10: =IFERROR(T10/S10,"") -> 0.78709577 | X10: =IFERROR(U10/S10,"") -> 0.87626868 | Y10: =IFERROR(V10/S10,"") -> 0.99654729 | Z10: =IFERROR(E10/B10,"") -> 32.245898 | AA10: =IFERROR(H10/B10,"") -> 39.091627 | AB10: =IFERROR(K10/B10,"") -> 4.0969284 | AC10: =IFERROR(C10/B10,"") -> 0.0090340514 | AD10: =IFERROR(G10/1000000,"") -> 25.028467 | AE10: =IFERROR(J10/1000000,"") -> 4.3603043 | AF10: =IFERROR(M10/1000000,"") -> 3.151653

Sheet Monthly_Capture
A1: year | B1: month | C1: period_start | D1: n_hours | E1: n_negative_price_hours | F1: sum_price | G1: sum_lf_onshore | H1: sum_price_x_lf_onshore | I1: sum_lf_offshore | J1: sum_price_x_lf_offshore | K1: sum_lf_solar | L1: sum_price_x_lf_solar | M1: ttf_eur_mwh_mean | N1: eua_eur_t_mean | O1: baseload_eur_mwh | P1: capture_onshore_eur_mwh | Q1: capture_offshore_eur_mwh | R1: capture_solar_eur_mwh | S1: capture_rate_onshore | T1: capture_rate_offshore | U1: capture_rate_solar | V1: mean_lf_onshore_pct | W1: mean_lf_offshore_pct | X1: mean_lf_solar_pct | Y1: pct_negative_price_hrs
A2: 2015 | B2: 1 | C2: 42005 | D2: 649 | E2: 12 | F2: 20149.43 | G2: 26015.08 | H2: 518503.75 | I2: 16461.588 | J2: 383112.88 | K2: 1468.7387 | L2: 45174.116 | M2: 19.682194 | O2: =IFERROR(F2/D2,"") -> 31.046888 | P2: =IFERROR(H2/G2,"") -> 19.930892 | Q2: =IFERROR(J2/I2,"") -> 23.273142 | R2: =IFERROR(L2/K2,"") -> 30.757083 | S2: =IFERROR(P2/O2,"") -> 0.64196105 | T2: =IFERROR(Q2/O2,"") -> 0.74961273 | U2: =IFERROR(R2/O2,"") -> 0.99066557 | V2: =IFERROR(G2/D2,"") -> 40.084868 | W2: =IFERROR(I2/D2,"") -> 25.364543 | X2: =IFERROR(K2/D2,"") -> 2.2630796 | Y2: =IFERROR(E2/D2,"") -> 0.018489985
A3: 2015 | B3: 2 | C3: 42036 | D3: 672 | E3: 8 | F3: 24658.49 | G3: 13926.878 | H3: 440786.7 | I3: 11480.628 | J3: 385949.03 | K3: 3381.1502 | L3: 126118.09 | M3: 22.502143 | O3: =IFERROR(F3/D3,"") -> 36.694182 | P3: =IFERROR(H3/G3,"") -> 31.650071 | Q3: =IFERROR(J3/I3,"") -> 33.617415 | R3: =IFERROR(L3/K3,"") -> 37.300351 | S3: =IFERROR(P3/O3,"") -> 0.86253652 | T3: =IFERROR(Q3/O3,"") -> 0.9161511 | U3: =IFERROR(R3/O3,"") -> 1.0165195 | V3: =IFERROR(G3/D3,"") -> 20.724521 | W3: =IFERROR(I3/D3,"") -> 17.084268 | X3: =IFERROR(K3/D3,"") -> 5.0314735 | Y3: =IFERROR(E3/D3,"") -> 0.011904762
A4: 2015 | B4: 3 | C4: 42064 | D4: 744 | E4: 14 | F4: 23285.59 | G4: 18693.668 | H4: 473206.47 | I4: 16144.379 | J4: 453955.47 | K4: 7501.7004 | L4: 229122.56 | M4: 21.803452 | O4: =IFERROR(F4/D4,"") -> 31.297836 | P4: =IFERROR(H4/G4,"") -> 25.31373 | Q4: =IFERROR(J4/I4,"") -> 28.118484 | R4: =IFERROR(L4/K4,"") -> 30.54275 | S4: =IFERROR(P4/O4,"") -> 0.8088013 | T4: =IFERROR(Q4/O4,"") -> 0.89841623 | U4: =IFERROR(R4/O4,"") -> 0.97587419 | V4: =IFERROR(G4/D4,"") -> 25.125898 | W4: =IFERROR(I4/D4,"") -> 21.699435 | X4: =IFERROR(K4/D4,"") -> 10.082931 | Y4: =IFERROR(E4/D4,"") -> 0.018817204
A5: 2015 | B5: 4 | C5: 42095 | D5: 720 | E5: 14 | F5: 21440.59 | G5: 13131.264 | H5: 338677.4 | I5: 13745.942 | J5: 374333.93 | K5: 11639.692 | L5: 307261.25 | M5: 22.1007 | O5: =IFERROR(F5/D5,"") -> 29.778597 | P5: =IFERROR(H5/G5,"") -> 25.791684 | Q5: =IFERROR(J5/I5,"") -> 27.232322 | R5: =IFERROR(L5/K5,"") -> 26.397712 | S5: =IFERROR(P5/O5,"") -> 0.86611479 | T5: =IFERROR(Q5/O5,"") -> 0.91449312 | U5: =IFERROR(R5/O5,"") -> 0.88646594 | V5: =IFERROR(G5/D5,"") -> 18.237866 | W5: =IFERROR(I5/D5,"") -> 19.091586 | X5: =IFERROR(K5/D5,"") -> 16.166239 | Y5: =IFERROR(E5/D5,"") -> 0.019444444
A6: 2015 | B6: 5 | C6: 42125 | D6: 744 | E6: 17 | F6: 18845.81 | G6: 13523.991 | H6: 309416.96 | I6: 19091.793 | J6: 457200.74 | K6: 11577.237 | L6: 290633.52 | M6: 20.532032 | O6: =IFERROR(F6/D6,"") -> 25.33039 | P6: =IFERROR(H6/G6,"") -> 22.879116 | Q6: =IFERROR(J6/I6,"") -> 23.947501 | R6: =IFERROR(L6/K6,"") -> 25.103876 | S6: =IFERROR(P6/O6,"") -> 0.90322797 | T6: =IFERROR(Q6/O6,"") -> 0.94540594 | U6: =IFERROR(R6/O6,"") -> 0.99105761 | V6: =IFERROR(G6/D6,"") -> 18.177407 | W6: =IFERROR(I6/D6,"") -> 25.661012 | X6: =IFERROR(K6/D6,"") -> 15.560803 | Y6: =IFERROR(E6/D6,"") -> 0.022849462
A7: 2015 | B7: 6 | C7: 42156 | D7: 720 | E7: 0 | F7: 21679.01 | G7: 10301.315 | H7: 289449.33 | I7: 16129.631 | J7: 462555.5 | K7: 11947.872 | L7: 363843.63 | M7: 20.521667 | O7: =IFERROR(F7/D7,"") -> 30.109736 | P7: =IFERROR(H7/G7,"") -> 28.098289 | Q7: =IFERROR(J7/I7,"") -> 28.677377 | R7: =IFERROR(L7/K7,"") -> 30.452588 | S7: =IFERROR(P7/O7,"") -> 0.93319613 | T7: =IFERROR(Q7/O7,"") -> 0.95242869 | U7: =IFERROR(R7/O7,"") -> 1.0113867 | V7: =IFERROR(G7/D7,"") -> 14.307382 | W7: =IFERROR(I7/D7,"") -> 22.402265 | X7: =IFERROR(K7/D7,"") -> 16.594267 | Y7: =IFERROR(E7/D7,"") -> 0
A8: 2015 | B8: 7 | C8: 42186 | D8: 744 | E8: 3 | F8: 26024.88 | G8: 14762.363 | H8: 434277.6 | I8: 23808.7 | J8: 737757.29 | K8: 12904.893 | L8: 456123.88 | M8: 20.926613 | O8: =IFERROR(F8/D8,"") -> 34.979677 | P8: =IFERROR(H8/G8,"") -> 29.417891 | Q8: =IFERROR(J8/I8,"") -> 30.986879 | R8: =IFERROR(L8/K8,"") -> 35.345033 | S8: =IFERROR(P8/O8,"") -> 0.84099951 | T8: =IFERROR(Q8/O8,"") -> 0.88585376 | U8: =IFERROR(R8/O8,"") -> 1.0104448 | V8: =IFERROR(G8/D8,"") -> 19.841886 | W8: =IFERROR(I8/D8,"") -> 32.000941 | X8: =IFERROR(K8/D8,"") -> 17.345287 | Y8: =IFERROR(E8/D8,"") -> 0.0040322581
A9: 2015 | B9: 8 | C9: 42217 | D9: 744 | E9: 0 | F9: 23520.37 | G9: 9429.7816 | H9: 279315.66 | I9: 19273.024 | J9: 578919.76 | K9: 12104.668 | L9: 371186.91 | M9: 19.607258 | O9: =IFERROR(F9/D9,"") -> 31.613401 | P9: =IFERROR(H9/G9,"") -> 29.620586 | Q9: =IFERROR(J9/I9,"") -> 30.037827 | R9: =IFERROR(L9/K9,"") -> 30.664775 | S9: =IFERROR(P9/O9,"") -> 0.93696299 | T9: =IFERROR(Q9/O9,"") -> 0.95016122 | U9: =IFERROR(R9/O9,"") -> 0.96999292 | V9: =IFERROR(G9/D9,"") -> 12.674438 | W9: =IFERROR(I9/D9,"") -> 25.904602 | X9: =IFERROR(K9/D9,"") -> 16.269715 | Y9: =IFERROR(E9/D9,"") -> 0
A10: 2015 | B10: 9 | C10: 42248 | D10: 720 | E10: 13 | F10: 22959.8 | G10: 13695.575 | H10: 380843.26 | I10: 25790.42 | J10: 778335.8 | K10: 8467.3001 | L10: 266295.6 | M10: 19.176667 | O10: =IFERROR(F10/D10,"") -> 31.888611 | P10: =IFERROR(H10/G10,"") -> 27.80776 | Q10: =IFERROR(J10/I10,"") -> 30.17926 | R10: =IFERROR(L10/K10,"") -> 31.449883 | S10: =IFERROR(P10/O10,"") -> 0.87202796 | T10: =IFERROR(Q10/O10,"") -> 0.94639619 | U10: =IFERROR(R10/O10,"") -> 0.98624186 | V10: =IFERROR(G10/D10,"") -> 19.021632 | W10: =IFERROR(I10/D10,"") -> 35.820028 | X10: =IFERROR(K10/D10,"") -> 11.760139 | Y10: =IFERROR(E10/D10,"") -> 0.018055556
A11: 2015 | B11: 10 | C11: 42278 | D11: 744 | E11: 0 | F11: 29290.46 | G11: 8855.8917 | H11: 323694.49 | I11: 27191.663 | J11: 1039977.8 | K11: 5107.7556 | L11: 191503.97 | M11: 18.287903 | O11: =IFERROR(F11/D11,"") -> 39.368898 | P11: =IFERROR(H11/G11,"") -> 36.551315 | Q11: =IFERROR(J11/I11,"") -> 38.2462 | R11: =IFERROR(L11/K11,"") -> 37.492783 | S11: =IFERROR(P11/O11,"") -> 0.92843126 | T11: =IFERROR(Q11/O11,"") -> 0.97148262 | U11: =IFERROR(R11/O11,"") -> 0.95234526 | V11: =IFERROR(G11/D11,"") -> 11.90308 | W11: =IFERROR(I11/D11,"") -> 36.547934 | X11: =IFERROR(K11/D11,"") -> 6.8652629 | Y11: =IFERROR(E11/D11,"") -> 0
A12: 2015 | B12: 11 | C12: 42309 | D12: 720 | E12: 18 | F12: 23314.81 | G12: 26581.534 | H12: 715026.09 | I12: 39586.554 | J12: 1186897.7 | K12: 2982.4489 | L12: 103475.87 | M12: 17.2 | O12: =IFERROR(F12/D12,"") -> 32.381681 | P12: =IFERROR(H12/G12,"") -> 26.899354 | Q12: =IFERROR(J12/I12,"") -> 29.982344 | R12: =IFERROR(L12/K12,"") -> 34.694933 | S12: =IFERROR(P12/O12,"") -> 0.83069666 | T12: =IFERROR(Q12/O12,"") -> 0.92590449 | U12: =IFERROR(R12/O12,"") -> 1.0714371 | V12: =IFERROR(G12/D12,"") -> 36.918797 | W12: =IFERROR(I12/D12,"") -> 54.981325 | X12: =IFERROR(K12/D12,"") -> 4.1422902 | Y12: =IFERROR(E12/D12,"") -> 0.025
A13: 2015 | B13: 12 | C13: 42339 | D13: 744 | E13: 11 | F13: 20672.46 | G13: 28857.208 | H13: 686997.03 | I13: 45912.099 | J13: 1187268.9 | K13: 2233.0753 | L13: 64992.464 | M13: 15.697581 | O13: =IFERROR(F13/D13,"") -> 27.785565 | P13: =IFERROR(H13/G13,"") -> 23.806774 | Q13: =IFERROR(J13/I13,"") -> 25.859608 | R13: =IFERROR(L13/K13,"") -> 29.104466 | S13: =IFERROR(P13/O13,"") -> 0.85680368 | T13: =IFERROR(Q13/O13,"") -> 0.93068499 | U13: =IFERROR(R13/O13,"") -> 1.0474672 | V13: =IFERROR(G13/D13,"") -> 38.78657 | W13: =IFERROR(I13/D13,"") -> 61.70981 | X13: =IFERROR(K13/D13,"") -> 3.0014453 | Y13: =IFERROR(E13/D13,"") -> 0.014784946
... A26: 2017 | B26: 1 | C26: 42736 | D26: 744 | E26: 3 | F26: 38989.43 | G26: 15970.615 | H26: 656130.28 | I26: 31607.103 | J26: 1419453.8 | K26: 2030.8675 | L26: 115727.73 | M26: 20.139516 | O26: =IFERROR(F26/D26,"") -> 52.405148 | P26: =IFERROR(H26/G26,"") -> 41.083594 | Q26: =IFERROR(J26/I26,"") -> 44.909329 | R26: =IFERROR(L26/K26,"") -> 56.984379 | S26: =IFERROR(P26/O26,"") -> 0.78396103 | T26: =IFERROR(Q26/O26,"") -> 0.85696407 | U26: =IFERROR(R26/O26,"") -> 1.0873813 | V26: =IFERROR(G26/D26,"") -> 21.465881 | W26: =IFERROR(I26/D26,"") -> 42.482665 | X26: =IFERROR(K26/D26,"") -> 2.7296607 | Y26: =IFERROR(E26/D26,"") -> 0.0040322581
A27: 2017 | B27: 2 | C27: 42767 | D27: 672 | E27: 5 | F27: 26665.62 | G27: 19352.594 | H27: 636989.45 | I27: 48788.693 | J27: 1839225.8 | K27: 3777.1685 | L27: 156957.09 | M27: 19.6375 | N27: 5.5778571 | O27: =IFERROR(F27/D27,"") -> 39.680982 | P27: =IFERROR(H27/G27,"") -> 32.91494 | Q27: =IFERROR(J27/I27,"") -> 37.697788 | R27: =IFERROR(L27/K27,"") -> 41.554166 | S27: =IFERROR(P27/O27,"") -> 0.82948904 | T27: =IFERROR(Q27/O27,"") -> 0.95002154 | U27: =IFERROR(R27/O27,"") -> 1.0472061 | V27: =IFERROR(G27/D27,"") -> 28.798503 | W27: =IFERROR(I27/D27,"") -> 72.602222 | X27: =IFERROR(K27/D27,"") -> 5.6207864 | Y27: =IFERROR(E27/D27,"") -> 0.0074404762
A28: 2017 | B28: 3 | C28: 42795 | D28: 744 | E28: 0 | F28: 23578.23 | G28: 18892.443 | H28: 543607.15 | I28: 38102.867 | J28: 1160872.8 | K28: 8217.3532 | L28: 252812.13 | M28: 15.883871 | N28: 5.5567742 | O28: =IFERROR(F28/D28,"") -> 31.691169 | P28: =IFERROR(H28/G28,"") -> 28.773788 | Q28: =IFERROR(J28/I28,"") -> 30.466809 | R28: =IFERROR(L28/K28,"") -> 30.76564 | S28: =IFERROR(P28/O28,"") -> 0.90794339 | T28: =IFERROR(Q28/O28,"") -> 0.96136589 | U28: =IFERROR(R28/O28,"") -> 0.97079534 | V28: =IFERROR(G28/D28,"") -> 25.393069 | W28: =IFERROR(I28/D28,"") -> 51.213531 | X28: =IFERROR(K28/D28,"") -> 11.04483 | Y28: =IFERROR(E28/D28,"") -> 0
A29: 2017 | B29: 4 | C29: 42826 | D29: 720 | E29: 18 | F29: 20679.25 | G29: 16292.258 | H29: 389079.73 | I29: 33141.511 | J29: 819587.14 | K29: 9810.2966 | L29: 247600.05 | M29: 16.1225 | N29: 5.2216667 | O29: =IFERROR(F29/D29,"") -> 28.721181 | P29: =IFERROR(H29/G29,"") -> 23.881265 | Q29: =IFERROR(J29/I29,"") -> 24.729927 | R29: =IFERROR(L29/K29,"") -> 25.238793 | S29: =IFERROR(P29/O29,"") -> 0.83148619 | T29: =IFERROR(Q29/O29,"") -> 0.86103449 | U29: =IFERROR(R29/O29,"") -> 0.87875195 | V29: =IFERROR(G29/D29,"") -> 22.628136 | W29: =IFERROR(I29/D29,"") -> 46.029876 | X29: =IFERROR(K29/D29,"") -> 13.625412 | Y29: =IFERROR(E29/D29,"") -> 0.025
A30: 2017 | B30: 5 | C30: 42856 | D30: 744 | E30: 15 | F30: 22773.92 | G30: 10753.334 | H30: 290223.79 | I30: 28518.689 | J30: 811870.51 | K30: 13024.031 | L30: 388605.77 | M30: 15.668548 | N30: 5.1741935 | O30: =IFERROR(F30/D30,"") -> 30.610108 | P30: =IFERROR(H30/G30,"") -> 26.989192 | Q30: =IFERROR(J30/I30,"") -> 28.468016 | R30: =IFERROR(L30/K30,"") -> 29.837596 | S30: =IFERROR(P30/O30,"") -> 0.8817085 | T30: =IFERROR(Q30/O30,"") -> 0.93002014 | U30: =IFERROR(R30/O30,"") -> 0.97476287 | V30: =IFERROR(G30/D30,"") -> 14.453406 | W30: =IFERROR(I30/D30,"") -> 38.331571 | X30: =IFERROR(K30/D30,"") -> 17.505418 | Y30: =IFERROR(E30/D30,"") -> 0.02016129
A31: 2017 | B31: 6 | C31: 42887 | D31: 720 | E31: 0 | F31: 21603.01 | G31: 14230.483 | H31: 364996.28 | I31: 27006.376 | J31: 703081.51 | K31: 13651.151 | L31: 401642.48 | M31: 15.085 | N31: 5.4456667 | O31: =IFERROR(F31/D31,"") -> 30.004181 | P31: =IFERROR(H31/G31,"") -> 25.648903 | Q31: =IFERROR(J31/I31,"") -> 26.033908 | R31: =IFERROR(L31/K31,"") -> 29.421877 | S31: =IFERROR(P31/O31,"") -> 0.85484431 | T31: =IFERROR(Q31/O31,"") -> 0.86767602 | U31: =IFERROR(R31/O31,"") -> 0.98059257 | V31: =IFERROR(G31/D31,"") -> 19.76456 | W31: =IFERROR(I31/D31,"") -> 37.508856 | X31: =IFERROR(K31/D31,"") -> 18.959932 | Y31: =IFERROR(E31/D31,"") -> 0
A32: 2017 | B32: 7 | C32: 42917 | D32: 744 | E32: 7 | F32: 24556.15 | G32: 11038.017 | H32: 325511.74 | I32: 20182.919 | J32: 606015.81 | K32: 12428.897 | L32: 401395.3 | M32: 15.08871 | N32: 5.7793548 | O32: =IFERROR(F32/D32,"") -> 33.005578 | P32: =IFERROR(H32/G32,"") -> 29.490056 | Q32: =IFERROR(J32/I32,"") -> 30.026173 | R32: =IFERROR(L32/K32,"") -> 32.295326 | S32: =IFERROR(P32/O32,"") -> 0.89348702 | T32: =IFERROR(Q32/O32,"") -> 0.90973026 | U32: =IFERROR(R32/O32,"") -> 0.97848087 | V32: =IFERROR(G32/D32,"") -> 14.836044 | W32: =IFERROR(I32/D32,"") -> 27.127579 | X32: =IFERROR(K32/D32,"") -> 16.705507 | Y32: =IFERROR(E32/D32,"") -> 0.0094086022
A33: 2017 | B33: 8 | C33: 42948 | D33: 744 | E33: 8 | F33: 22956.78 | G33: 10586.266 | H33: 288470.91 | I33: 24358.614 | J33: 659812.1 | K33: 11707.655 | L33: 353650.26 | M33: 16.033065 | N33: 6.3251613 | O33: =IFERROR(F33/D33,"") -> 30.855887 | P33: =IFERROR(H33/G33,"") -> 27.249543 | Q33: =IFERROR(J33/I33,"") -> 27.087423 | R33: =IFERROR(L33/K33,"") -> 30.206755 | S33: =IFERROR(P33/O33,"") -> 0.88312299 | T33: =IFERROR(Q33/O33,"") -> 0.87786889 | U33: =IFERROR(R33/O33,"") -> 0.97896245 | V33: =IFERROR(G33/D33,"") -> 14.228852 | W33: =IFERROR(I33/D33,"") -> 32.740073 | X33: =IFERROR(K33/D33,"") -> 15.736095 | Y33: =IFERROR(E33/D33,"") -> 0.010752688
A34: 2017 | B34: 9 | C34: 42979 | D34: 720 | E34: 8 | F34: 24694.63 | G34: 12772.432 | H34: 354882.71 | I34: 21860.41 | J34: 665564.97 | K34: 7832.4778 | L34: 278481.81 | M34: 17.149167 | N34: 7.368 | O34: =IFERROR(F34/D34,"") -> 34.298097 | P34: =IFERROR(H34/G34,"") -> 27.785054 | Q34: =IFERROR(J34/I34,"") -> 30.446134 | R34: =IFERROR(L34/K34,"") -> 35.554752 | S34: =IFERROR(P34/O34,"") -> 0.81010483 | T34: =IFERROR(Q34/O34,"") -> 0.88769165 | U34: =IFERROR(R34/O34,"") -> 1.0366392 | V34: =IFERROR(G34/D34,"") -> 17.739489 | W34: =IFERROR(I34/D34,"") -> 30.36168 | X34: =IFERROR(K34/D34,"") -> 10.878441 | Y34: =IFERROR(E34/D34,"") -> 0.011111111
A35: 2017 | B35: 10 | C35: 43009 | D35: 744 | E35: 39 | F35: 21046.76 | G35: 24844.759 | H35: 489085.92 | I35: 47913.424 | J35: 1248675.7 | K35: 5418.6749 | L35: 158001.27 | M35: 17.11129 | N35: 7.826129 | O35: =IFERROR(F35/D35,"") -> 28.288656 | P35: =IFERROR(H35/G35,"") -> 19.685678 | Q35: =IFERROR(J35/I35,"") -> 26.061083 | R35: =IFERROR(L35/K35,"") -> 29.158654 | S35: =IFERROR(P35/O35,"") -> 0.69588593 | T35: =IFERROR(Q35/O35,"") -> 0.9212556 | U35: =IFERROR(R35/O35,"") -> 1.0307543 | V35: =IFERROR(G35/D35,"") -> 33.393494 | W35: =IFERROR(I35/D35,"") -> 64.399764 | X35: =IFERROR(K35/D35,"") -> 7.2831652 | Y35: =IFERROR(E35/D35,"") -> 0.052419355
A36: 2017 | B36: 11 | C36: 43040 | D36: 720 | E36: 1 | F36: 29072.88 | G36: 19207.169 | H36: 598074.84 | I36: 34785.686 | J36: 1151704.6 | K36: 2064.6022 | L36: 88715.072 | M36: 19.563333 | N36: 8.1413333 | O36: =IFERROR(F36/D36,"") -> 40.379 | P36: =IFERROR(H36/G36,"") -> 31.138105 | Q36: =IFERROR(J36/I36,"") -> 33.108579 | R36: =IFERROR(L36/K36,"") -> 42.969572 | S36: =IFERROR(P36/O36,"") -> 0.77114601 | T36: =IFERROR(Q36/O36,"") -> 0.81994549 | U36: =IFERROR(R36/O36,"") -> 1.0641564 | V36: =IFERROR(G36/D36,"") -> 26.676624 | W36: =IFERROR(I36/D36,"") -> 48.313453 | X36: =IFERROR(K36/D36,"") -> 2.867503 | Y36: =IFERROR(E36/D36,"") -> 0.0013888889
A37: 2017 | B37: 12 | C37: 43070 | D37: 744 | E37: 43 | F37: 22848.61 | G37: 27907.911 | H37: 619636.26 | I37: 42284.593 | J37: 1075863.8 | K37: 1217.3101 | L37: 40105.664 | M37: 20.872581 | N37: 8.17 | O37: =IFERROR(F37/D37,"") -> 30.710497 | P37: =IFERROR(H37/G37,"") -> 22.20289 | Q37: =IFERROR(J37/I37,"") -> 25.443399 | R37: =IFERROR(L37/K37,"") -> 32.946137 | S37: =IFERROR(P37/O37,"") -> 0.72297395 | T37: =IFERROR(Q37/O37,"") -> 0.82849192 | U37: =IFERROR(R37/O37,"") -> 1.0727972 | V37: =IFERROR(G37/D37,"") -> 37.510633 | W37: =IFERROR(I37/D37,"") -> 56.83413 | X37: =IFERROR(K37/D37,"") -> 1.6361694 | Y37: =IFERROR(E37/D37,"") -> 0.057795699
A38: 2018 | B38: 1 | C38: 43101 | D38: 744 | E38: 43 | F38: 21948.64 | G38: 27605.041 | H38: 617272.8 | I38: 37004.924 | J38: 950173.84 | K38: 1794.0723 | L38: 61732.242 | M38: 18.724194 | N38: 8.9483871 | O38: =IFERROR(F38/D38,"") -> 29.50086 | P38: =IFERROR(H38/G38,"") -> 22.360872 | Q38: =IFERROR(J38/I38,"") -> 25.676957 | R38: =IFERROR(L38/K38,"") -> 34.409006 | S38: =IFERROR(P38/O38,"") -> 0.75797357 | T38: =IFERROR(Q38/O38,"") -> 0.87037993 | U38: =IFERROR(R38/O38,"") -> 1.166373 | V38: =IFERROR(G38/D38,"") -> 37.10355 | W38: =IFERROR(I38/D38,"") -> 49.737801 | X38: =IFERROR(K38/D38,"") -> 2.4113875 | Y38: =IFERROR(E38/D38,"") -> 0.057795699
... A100: 2023 | B100: 3 | C100: 44986 | D100: 23 | E100: 0 | F100: 3298.16 | G100: 0 | H100: 0 | I100: 0 | J100: 0 | K100: 0 | L100: 0 | M100: 49.6 | N100: 96.92 | O100: =IFERROR(F100/D100,"") -> 143.39826 | P100: =IFERROR(H100/G100,"") | Q100: =IFERROR(J100/I100,"") | R100: =IFERROR(L100/K100,"") | S100: =IFERROR(P100/O100,"") | T100: =IFERROR(Q100/O100,"") | U100: =IFERROR(R100/O100,"") | V100: =IFERROR(G100/D100,"") -> 0 | W100: =IFERROR(I100/D100,"") -> 0 | X100: =IFERROR(K100/D100,"") -> 0 | Y100: =IFERROR(E100/D100,"") -> 0

Sheet Sens_ExNegative
A1: year | B1: exneg_n_hours | C1: exneg_sum_price | D1: exneg_sum_lf_onshore | E1: exneg_sum_price_x_lf_onshore | F1: exneg_sum_lf_offshore | G1: exneg_sum_price_x_lf_offshore | H1: exneg_sum_lf_solar | I1: exneg_sum_price_x_lf_solar | J1: exneg_baseload_eur_mwh | K1: exneg_capture_onshore_eur_mwh | L1: exneg_capture_offshore_eur_mwh | M1: exneg_capture_solar_eur_mwh | N1: exneg_capture_rate_onshore | O1: exneg_capture_rate_offshore | P1: exneg_capture_rate_solar
A2: 2015 | B2: 8555 | C2: 276815.35 | D2: 186188.57 | E2: 5242257.1 | F2: 266422.44 | G2: 8073386 | H2: 90251.083 | I2: 2833390.6 | J2: =IFERROR(C2/B2,"") -> 32.357142 | K2: =IFERROR(E2/D2,"") -> 28.155632 | L2: =IFERROR(G2/F2,"") -> 30.30295 | M2: =IFERROR(I2/H2,"") -> 31.394533 | N2: =IFERROR(K2/J2,"") -> 0.87015202 | O2: =IFERROR(L2/J2,"") -> 0.93651504 | P2: =IFERROR(M2/J2,"") -> 0.97025049
A3: 2016 | B3: 8687 | C3: 256306.87 | D3: 171991.25 | E3: 4453660.2 | F3: 313368.06 | G3: 8627959.5 | H3: 87508.809 | I3: 2416328.2 | J3: =IFERROR(C3/B3,"") -> 29.504647 | K3: =IFERROR(E3/D3,"") -> 25.89469 | L3: =IFERROR(G3/F3,"") -> 27.532989 | M3: =IFERROR(I3/H3,"") -> 27.612399 | N3: =IFERROR(K3/J3,"") -> 0.87764785 | O3: =IFERROR(L3/J3,"") -> 0.93317467 | P3: =IFERROR(M3/J3,"") -> 0.93586611
A4: 2017 | B4: 8613 | C4: 303335.02 | D4: 193540.01 | E4: 5784391.5 | F4: 388136.19 | G4: 12407903 | H4: 89303.012 | I4: 2942789 | J4: =IFERROR(C4/B4,"") -> 35.218277 | K4: =IFERROR(E4/D4,"") -> 29.887317 | L4: =IFERROR(G4/F4,"") -> 31.967911 | M4: =IFERROR(I4/H4,"") -> 32.952853 | N4: =IFERROR(K4/J4,"") -> 0.84863086 | O4: =IFERROR(L4/J4,"") -> 0.90770798 | P4: =IFERROR(M4/J4,"") -> 0.93567476
A5: 2018 | B5: 8627 | C5: 391416.53 | D5: 185418.49 | E5: 7339246 | F5: 343209.52 | G5: 14485940 | H5: 99655.851 | I5: 4463479.8 | J5: =IFERROR(C5/B5,"") -> 45.371106 | K5: =IFERROR(E5/D5,"") -> 39.58206 | L5: =IFERROR(G5/F5,"") -> 42.20728 | M5: =IFERROR(I5/H5,"") -> 44.788939 | N5: =IFERROR(K5/J5,"") -> 0.87240677 | O5: =IFERROR(L5/J5,"") -> 0.93026782 | P5: =IFERROR(M5/J5,"") -> 0.98716878
A6: 2019 | B6: 8549 | C6: 333617.78 | D6: 185379.37 | E6: 6533546.3 | F6: 359261.85 | G6: 13197962 | H6: 95515.679 | I6: 3532187.3 | J6: =IFERROR(C6/B6,"") -> 39.024188 | K6: =IFERROR(E6/D6,"") -> 35.244192 | L6: =IFERROR(G6/F6,"") -> 36.736329 | M6: =IFERROR(I6/H6,"") -> 36.980183 | N6: =IFERROR(K6/J6,"") -> 0.90313711 | O6: =IFERROR(L6/J6,"") -> 0.94137331 | P6: =IFERROR(M6/J6,"") -> 0.94762211
A7: 2020 | B7: 8486 | C7: 272284.93 | D7: 181146.54 | E7: 5014723.6 | F7: 338193.87 | G7: 10044862 | H7: 90582.224 | I7: 2543177.6 | J7: =IFERROR(C7/B7,"") -> 32.086369 | K7: =IFERROR(E7/D7,"") -> 27.683242 | L7: =IFERROR(G7/F7,"") -> 29.70149 | M7: =IFERROR(I7/H7,"") -> 28.075901 | N7: =IFERROR(K7/J7,"") -> 0.86277266 | O7: =IFERROR(L7/J7,"") -> 0.92567314 | P7: =IFERROR(M7/J7,"") -> 0.87501023
A8: 2021 | B8: 8621 | C8: 850678.14 | D8: 160820.21 | E8: 13541540 | F8: 302982.44 | G8: 28733871 | H8: 86822.797 | I8: 6927261.3 | J8: =IFERROR(C8/B8,"") -> 98.675112 | K8: =IFERROR(E8/D8,"") -> 84.202975 | L8: =IFERROR(G8/F8,"") -> 94.836751 | M8: =IFERROR(I8/H8,"") -> 79.786203 | N8: =IFERROR(K8/J8,"") -> 0.85333549 | O8: =IFERROR(L8/J8,"") -> 0.96110102 | P8: =IFERROR(M8/J8,"") -> 0.80857474
A9: 2022 | B9: 8690 | C9: 2062601.8 | D9: 183615.71 | E9: 31457504 | F9: 315765.53 | G9: 62097914 | H9: 105758.16 | I9: 24022204 | J9: =IFERROR(C9/B9,"") -> 237.35349 | K9: =IFERROR(E9/D9,"") -> 171.32251 | L9: =IFERROR(G9/F9,"") -> 196.6583 | M9: =IFERROR(I9/H9,"") -> 227.14279 | N9: =IFERROR(K9/J9,"") -> 0.72180321 | O9: =IFERROR(L9/J9,"") -> 0.82854609 | P9: =IFERROR(M9/J9,"") -> 0.95698105
A10: 2023 | B10: 1426 | C10: 177356.54 | D10: 45792.248 | E10: 4502098.7 | F10: 55662.966 | G10: 6075601.8 | H10: 5823.6637 | I10: 724047.33 | J10: =IFERROR(C10/B10,"") -> 124.37345 | K10: =IFERROR(E10/D10,"") -> 98.315738 | L10: =IFERROR(G10/F10,"") -> 109.1498 | M10: =IFERROR(I10/H10,"") -> 124.32849 | N10: =IFERROR(K10/J10,"") -> 0.79048815 | O10: =IFERROR(L10/J10,"") -> 0.87759729 | P10: =IFERROR(M10/J10,"") -> 0.99963852

Sheet Sens_Weighting
A1: year | B1: onshore_wind_lf_weighted | C1: onshore_wind_gen_weighted | D1: onshore_wind_diff | E1: offshore_wind_lf_weighted | F1: offshore_wind_gen_weighted | G1: offshore_wind_diff | H1: solar_pv_lf_weighted | I1: solar_pv_gen_weighted | J1: solar_pv_diff
A2: 2015 | B2: 26.913038 | C2: 26.913037 | D2: 4.5898084e-07 | E2: 29.538486 | F2: 29.593128 | G2: -0.054642192 | H2: 30.881052 | I2: 30.881052 | J2: -3.5527137e-15
A3: 2016 | B3: 24.471959 | C3: 24.515225 | D3: -0.043266169 | E3: 26.653935 | F3: 26.873995 | G3: -0.22005988 | H3: 26.747589 | I3: 26.764101 | J3: -0.016512571
A4: 2017 | B4: 27.529038 | C4: 27.481861 | D4: 0.047177459 | E4: 30.51487 | F4: 30.205873 | G4: 0.30899738 | H4: 31.626226 | I4: 31.63322 | J4: -0.0069937419
A5: 2018 | B5: 37.357557 | C5: 37.451885 | D5: -0.094327481 | E5: 41.008327 | F5: 41.555024 | G5: -0.54669678 | H5: 43.839506 | I5: 43.851263 | J5: -0.011756168
A6: 2019 | B6: 32.364352 | C6: 32.346749 | D6: 0.017602384 | E6: 34.897698 | F6: 34.753409 | G6: 0.14428899 | H6: 34.913854 | I6: 34.934802 | J6: -0.020947464
A7: 2020 | B7: 24.636674 | C7: 24.636674 | D7: -3.5527137e-15 | E7: 27.77235 | F7: 27.842084 | G7: -0.069734522 | H7: 24.599707 | I7: 24.599707 | J7: -3.5527137e-15
A8: 2021 | B8: 80.509632 | C8: 80.539359 | D8: -0.029727488 | E8: 92.326684 | F8: 92.33552 | G8: -0.008836005 | H8: 75.552226 | I8: 75.559446 | J8: -0.0072197081
A9: 2022 | B9: 168.38444 | C9: 168.38444 | D9: -2.8421709e-14 | E9: 194.35684 | F9: 194.35684 | G9: -8.5265128e-14 | H9: 223.54205 | I9: 223.54205 | J9: -2.8421709e-14
A10: 2023 | B10: 96.99327 | C10: 96.99327 | D10: -1.4210855e-14 | E10: 107.98199 | F10: 107.98199 | G10: 0 | H10: 122.80384 | I10: 122.80384 | J10: -1.4210855e-14

Sheet Monthly_Panel
A1: month_start | B1: year | C1: month | D1: baseload_eur_mwh | E1: capture_onshore_eur_mwh | F1: capture_rate_onshore | G1: ttf_eur_mwh | H1: eua_eur_t | I1: srmc_ccgt_eur_mwh | J1: onshore_wind_gen_gwh | K1: offshore_wind_gen_gwh | L1: solar_pv_gen_gwh
A2: 42005 | B2: 2015 | C2: 1 | D2: 27.773185 | E2: 21.166898 | F2: 0.76213432 | G2: 19.682194 | J2: 9078.6812 | K2: 261.52525 | L2: 559.6735
A3: 42036 | B3: 2015 | C3: 2 | D3: 36.694182 | E3: 33.018632 | F3: 0.8998329 | G3: 22.502143 | J3: 4860.1692 | K3: 283.5055 | L3: 1288.4117
A4: 42064 | B4: 2015 | C4: 3 | D4: 31.297836 | E4: 25.897548 | F4: 0.82745492 | G4: 21.803452 | J4: 6523.6722 | K4: 433.299 | L4: 2858.5772
A5: 42095 | B5: 2015 | C5: 4 | D5: 29.778597 | E5: 27.011168 | F5: 0.9070665 | G5: 22.1007 | J5: 4582.5175 | K5: 377.10475 | L5: 4435.389
A6: 42125 | B6: 2015 | C6: 5 | D6: 25.33039 | E6: 24.186798 | F6: 0.95485296 | G6: 20.532032 | J6: 4719.5705 | K6: 567.389 | L6: 4411.59
A7: 42156 | B7: 2015 | C7: 6 | D7: 30.109736 | E7: 28.840794 | F7: 0.9578561 | G7: 20.521667 | J7: 3594.9288 | K7: 479.3565 | L7: 4552.8233
A8: 42186 | B8: 2015 | C8: 7 | D8: 34.979677 | E8: 30.720061 | F8: 0.87822598 | G8: 20.926613 | J8: 5151.7347 | K8: 707.57075 | L8: 4917.503
A9: 42217 | B9: 2015 | C9: 8 | D9: 31.613401 | E9: 30.368512 | F9: 0.9606215 | G9: 19.607258 | J9: 3290.783 | K9: 572.775 | L9: 4612.5712
A10: 42248 | B10: 2015 | C10: 9 | D10: 31.888611 | E10: 28.700531 | F10: 0.90002449 | G10: 19.176667 | J10: 4779.4495 | K10: 766.4655 | L10: 3226.526
A11: 42278 | B11: 2015 | C11: 10 | D11: 39.368898 | E11: 37.077545 | F11: 0.94179789 | G11: 18.287903 | J11: 3090.5082 | K11: 888.42775 | L11: 1946.3473
A12: 42309 | B12: 2015 | C12: 11 | D12: 32.381681 | E12: 28.074048 | F12: 0.86697318 | G12: 17.2 | J12: 9276.3612 | K12: 1295.755 | L12: 1136.4838
A13: 42339 | B13: 2015 | C13: 12 | D13: 27.785565 | E13: 24.922729 | F13: 0.89696682 | G13: 15.697581 | J13: 10070.531 | K13: 1502.804 | L13: 850.9295
... A26: 42736 | B26: 2017 | C26: 1 | D26: 52.405148 | E26: 42.509549 | F26: 0.81117125 | G26: 20.139516 | J26: 6599.1897 | K26: 1228.3177 | L26: 798.42225
A27: 42767 | B27: 2017 | C27: 2 | D27: 39.680982 | E27: 34.017748 | F27: 0.85728089 | G27: 19.6375 | H27: 5.5778571 | I27: 41.22725 | J27: 7996.651 | K27: 1903.158 | L27: 1484.969
A28: 42795 | B28: 2017 | C28: 3 | D28: 31.691169 | E28: 29.668506 | F28: 0.9361758 | G28: 15.883871 | H28: 5.5567742 | I28: 33.712613 | J28: 7806.513 | K28: 1487.2952 | L28: 3230.5985
A29: 42826 | B29: 2017 | C29: 4 | D29: 28.721181 | E29: 25.019293 | F29: 0.87110951 | G29: 16.1225 | H29: 5.2216667 | I29: 34.072583 | J29: 6732.095 | K29: 1398.011 | L29: 3856.8538
A30: 42856 | B30: 2017 | C30: 5 | D30: 30.610108 | E30: 27.960902 | F30: 0.91345325 | G30: 15.668548 | H30: 5.1741935 | I30: 33.148065 | J30: 4443.366 | K30: 1203.2387 | L30: 5120.3122
A31: 42887 | B31: 2017 | C31: 6 | D31: 30.004181 | E31: 26.833937 | F31: 0.89433994 | G31: 15.085 | H31: 5.4456667 | I31: 32.075983 | J31: 5880.1528 | K31: 1247.7777 | L31: 5366.8605
A32: 42917 | B32: 2017 | C32: 7 | D32: 33.005578 | E32: 30.805133 | F32: 0.93333112 | G32: 15.08871 | H32: 5.7793548 | I32: 32.200194 | J32: 4560.9995 | K32: 932.513 | L32: 4886.3395
A33: 42948 | B33: 2017 | C33: 8 | D33: 30.855887 | E33: 28.374999 | F33: 0.91959757 | G33: 16.033065 | H33: 6.3251613 | I33: 34.279935 | J33: 4374.3323 | K33: 1125.443 | L33: 4602.7878
A34: 42979 | B34: 2017 | C34: 9 | D34: 34.298097 | E34: 28.425902 | F34: 0.82878948 | G34: 17.149167 | H34: 7.368 | I34: 36.877133 | J34: 5277.674 | K34: 1010.0182 | L34: 3079.2872
A35: 43009 | B35: 2017 | C35: 10 | D35: 28.288656 | E35: 20.9053 | F35: 0.73899941 | G35: 17.11129 | H35: 7.826129 | I35: 36.961726 | J35: 10266.059 | K35: 2214.034 | L35: 2130.3165
A36: 43040 | B36: 2017 | C36: 11 | D36: 40.379 | E36: 32.199181 | F36: 0.79742392 | G36: 19.563333 | H36: 8.1413333 | I36: 41.976133 | J36: 8615.9682 | K36: 1643.0103 | L36: 831.0175
A37: 43070 | B37: 2017 | C37: 12 | D37: 30.710497 | E37: 22.965016 | F37: 0.74779044 | G37: 20.872581 | H37: 8.17 | I37: 44.604661 | J37: 12699.789 | K37: 2025.6085 | L37: 495.41625
A38: 43101 | B38: 2018 | C38: 1 | D38: 29.50086 | E38: 24.345045 | F38: 0.82523171 | G38: 18.724194 | H38: 8.9483871 | I38: 40.580323 | J38: 12561.965 | K38: 1883.262 | L38: 730.14475
... A99: 44958 | B99: 2023 | C99: 2 | D99: 128.39092 | E99: 109.74586 | F99: 0.85477894 | G99: 53.532143 | H99: 95 | I99: 140.31429 | J99: 10359.588 | K99: 1631.1903 | L99: 2296.8325

Sheet Correlations
A1: Monthly Pearson correlations
A2: Sample: 73 monthly observations where TTF and EUA are both available (Feb-2017 onward for the EUA columns).
B4: baseload_eur_mwh | C4: capture_onshore_eur_mwh | D4: capture_rate_onshore | E4: ttf_eur_mwh | F4: eua_eur_t | G4: srmc_ccgt_eur_mwh
A5: baseload_eur_mwh | B5: 1 | C5: 0.98919081 | D5: -0.018653831 | E5: 0.99071928 | F5: 0.81128121 | G5: 0.99090327
A6: capture_onshore_eur_mwh | B6: 0.98919081 | C6: 1 | D6: 0.083842908 | E6: 0.97899094 | F6: 0.77534087 | G6: 0.97655316
A7: capture_rate_onshore | B7: -0.018653831 | C7: 0.083842908 | D7: 1 | E7: -0.032506374 | F7: -0.13066128 | G7: -0.042861212
A8: ttf_eur_mwh | B8: 0.99071928 | C8: 0.97899094 | D8: -0.032506374 | E8: 1 | F8: 0.7990155 | G8: 0.99820974
A9: eua_eur_t | B9: 0.81128121 | C9: 0.77534087 | D9: -0.13066128 | E9: 0.7990155 | F9: 1 | G9: 0.83354981
A10: srmc_ccgt_eur_mwh | B10: 0.99090327 | C10: 0.97655316 | D10: -0.042861212 | E10: 0.99820974 | F10: 0.83354981 | G10: 1
A13: Reading
A14: Baseload is ~98% correlated with the implied CCGT short-run marginal cost (2·TTF + 0.35·EUA) - i.e. gas sets the price almost monotonically over the full sample. The onshore-wind capture rate is negatively correlated with both TTF and EUA: when fuel costs rise, wind's relative capture falls because the price spread between still and windy hours widens.

Sheet Regressions
A1: OLS regressions - monthly data
A2: Coefficients from plain OLS. Standard errors in brackets below each coefficient. * Units: baseload & capture prices in €/MWh, TTF in €/MWh, EUA in €/t, capture rate as a decimal.
A4: Specification | B4: Sample (n) | C4: α (intercept) | D4: β TTF (€/MWh) | E4: γ EUA (€/t) | F4: R² | G4: Adj R²
A5: baseload ~ TTF (2015-2023 monthly) | B5: 98 | C5: 4.35 | D5: 1.913 | F5: 0.979 | G5: 0.979
C6: (1.48) | D6: (0.029)
A8: baseload ~ TTF + EUA (post-Feb-2017) | B8: 73 | C8: 4.06 | D8: 1.81 | E8: 0.168 | F8: 0.983 | G8: 0.982
C9: (2.32) | D9: (0.050) | E9: (0.081)
A11: capture_onshore ~ TTF + EUA | B11: 73 | C11: 5.76 | D11: 1.705 | E11: -0.053 | F11: 0.959 | G11: 0.957
C12: (3.22) | D12: (0.069) | E12: (0.112)
A14: capture_rate_onshore ~ TTF + EUA | B14: 73 | C14: 0.8838 | D14: 0.000298 | E14: -0.000701 | F14: 0.031 | G14: 0.004
C15: (0.0136) | D15: (0.000293) | E15: (0.000474)
A17: capture_rate_onshore ~ TTF + EUA + fleet_LF | B17: 73 | C17: 0.9355 | D17: 8e-05 | E17: -0.000306 | F17: 0.143 | G17: 0.105
A18: fleet_LF coef: -0.279 (se 0.093)
A24: capture_rate ~ TTF + EUA + post2021 + TTF×post2021 | B24: 73 | C24: 0.8503 | D24: 0.001963 | E24: -0.000366 | F24: 0.053 | G24: -0.003
A25: post2021 intercept shift: +0.0021 | TTF×post2021 slope: -0.001646 (se 0.001575)
A27: Regime split on baseload ~ TTF (single regressor)
A28: Regime | B28: n | C28: α | D28: β TTF | E28: R²
A29: post-Jul-2021 | B29: 20 | C29: 1.62 | D29: 1.942 | E29: 0.963
C30: (9.82) | D30: (0.090)
A31: pre-Jul-2021 | B31: 78 | C31: 15.53 | D31: 1.239 | E31: 0.418
C32: (2.93) | D32: (0.168)
A34: Interpretation
A35: 1. Gas-only regression (n=98): baseload = €4.4 + 1.91·TTF with R² = 0.98. β = 1.91 is the implied monthly market heat rate and is bang-in-line with a ~52% efficient CCGT sitting on the margin most hours. Simply put: TTF alone explains 98% of monthly German power price variation since 2015.
A36: 2. Adding EUA (post-Feb 2017, n=73): β_TTF = 1.81, γ_EUA = 0.17 (t=2.1). A €10/t EUA move adds €1.7/MWh to baseload on top of TTF pass-through - consistent with the residual carbon cost borne by the coal/lignite units that still set price in off-peak hours.
A37: 3. Onshore capture price tracks TTF almost 1:1 (β = 1.70, R² = 0.96). A €10/MWh TTF move lifts wind capture by ~€17; baseload moves by ~€18. Wind therefore under-recovers ~€1/MWh for every €10 TTF move - the cannibalisation 'tax'.
A38: 4. Capture rate on TTF + EUA alone has R² = 0.03 across the full sample - the TTF level itself doesn't predict capture rate, because the relationship is non-linear and regime-dependent.
A39: 5. Regime-interacted model resolves this: base capture rate is ~86% pre-July-2021, and the TTF×post2021 interaction is negative and significant. Same TTF level has a meaningfully larger cannibalisation impact once gas dominates price formation - i.e. the 2022 drop is not a level effect but a regime shift in how fuel-cost shocks propagate through the capture rate.
A40: 6. Baseload ~ TTF regime split corroborates: R² = 0.42 pre-Jul-2021 (slope 1.24), R² = 0.96 post-Jul-2021 (slope 1.94). The slope steepening confirms CCGTs became the dominant marginal plant, and the R² jump shows gas now drives nearly all variation in baseload. EUA dropped from a secondary driver (R² with power 0.81) to essentially co-moving with TTF.

Sheet Public_Benchmarks
A1: Public-benchmark cross-check
A3: Purpose | B3: Sanity-check our annual figures against public sources. Small deviations are expected because the case-study hourly dataset is a modelled capacity × load-factor series, not metered settlement data.
A5: Year | B5: Metric | C5: Public value (€/MWh) | D5: Source | E5: Our value (€/MWh) | F5: Diff %
A6: 2022 | B6: German day-ahead baseload | C6: 235.45 | D6: EPEX SPOT Annual Market Review 2022 | E6: 235.44 | F6: -4.2471862e-05
A7: 2019 | B7: German onshore wind market value | C7: 32.81 | D7: Energy-Charts / Fraunhofer ISE (Marktwert Wind Onshore) | E7: 32.36 | F7: -0.013715331
A8: 2022 | B8: German onshore wind capture price | C8: 162.7 | D8: Deutsche WindGuard - Status of Onshore Wind 2022 | E8: 168.38 | F8: 0.034910879
A11: Read-across
A12: • Baseload 2022 matches EPEX to the cent, confirming the price series is a correct DE day-ahead auction hourly feed. • Onshore wind capture 2019 prints 1.4 % below Fraunhofer’s reported market value - well within the noise introduced by using a modelled fleet LF profile. • Onshore wind capture 2022 prints 3.5 % above Deutsche WindGuard. The direction of the deviation (our capture price slightly higher) is consistent with the case-study profile being smoother than the real metered fleet and therefore cannibalising a little less during extreme low-price hours. • Order of magnitude, relative year-on-year dynamics and capture-rate trajectory all reconcile - conclusions drawn from the series are robust.

Sheet Methodology
A1: Methodology
A4: Choice of weight - load factor vs production
B5: Capture price can be written as sum(price × production) / sum(production). Substituting production = load_factor × installed_capacity, and noting that installed capacity is constant within a year in this dataset, installed capacity factors out of both numerator and denominator, making load-factor-weighted and production-weighted capture prices arithmetically identical within a year. This is verified explicitly on the Sens_Weighting sheet.
B6: The LF formulation is preferred because (i) it has a clean per-MW interpretation - a representative 1 MW onshore wind asset experiences exactly this capture price if its hourly profile matches the fleet - and (ii) when pooling or comparing across years with different fleet sizes, LF-weighting treats each year on equal footing rather than over-weighting later years where the fleet is larger.
A8: Timestamps
B9: All aggregation is done on UTC timestamps. Europe/Berlin has DST shifts (23 hours in March, 25 in October, local time), but the source data is in UTC, so every calendar year has exactly 8760 (non-leap) or 8784 (leap) hours. No duplication or dropping of hours is required.
A11: Handling of the 2015 price gap
B12: Hours 2015-01-01 00:00 through 2015-01-04 22:00 (95 hours) have no day-ahead price in the source. Because the aggregator sums price × LF and drops NaN, these hours automatically do not contribute to the capture-price numerator; they are also excluded from n_hours via the 'count of non-missing price' logic. This makes 2015 a ~8665-hour year for aggregation purposes; the effect on the annual capture price is sub-€0.05/MWh.
A14: Treatment of negative prices
B15: Included in the headline figures. A wind asset receiving merchant revenue realises the negative price; excluding these hours overstates the commercial capture price, especially in high-wind hours. A sensitivity removing all hours with price < 0 is provided so the magnitude of the effect is visible.
A17: Capture rate definition
